<?xml version="1.0" ?>
<sdf version="1.5">
  <model name="tetherball">
    <!-- Base Link -->
    <link name="base">
      <kinematic>true</kinematic>
      <pose>0 0 0.05 0 0 0</pose>
      <collision name="collision">
        <geometry>
          <box>
            <size>0.2 0.2 0.1</size>
          </box>
        </geometry>
      </collision>
      <visual name="visual">
        <geometry>
          <box>
            <size>0.2 0.2 0.1</size>
          </box>
        </geometry>
	<material>
          <script>
            <name>Gazebo/Gray</name>
            <uri>file://media/materials/scripts/gazebo.material</uri>
          </script>
	</material>
      </visual>
    </link>

    <!-- Ball in Socket Joint -->
    <joint name="hinge" type="ball">
      <parent>base</parent>
      <child>rod</child>
      <pose relative_to="base">0 0 0 0 0 0</pose>
    </joint>

    <!-- Rod -->
    <link name="rod">
      <pose relative_to="hinge">0 0 -0.5 0 0 0</pose>
      <inertial>
        <mass>0.100</mass>
        <inertia>
          <ixx>0.008333</ixx>
          <iyy>0.008333</iyy>
          <izz>0.000001</izz>
          <ixy>0</ixy>
          <ixz>0</ixz>
          <iyz>0</iyz>
        </inertia>
      </inertial>
      <collision name="collision">
        <geometry>
          <cylinder>
            <radius>0.005</radius>
            <length>1.0</length>
          </cylinder>
        </geometry>
      </collision>
      <visual name="visual">
        <geometry>
          <cylinder>
            <radius>0.005</radius>
            <length>1.0</length>
          </cylinder>
        </geometry>
	<material>
          <script>
            <name>Gazebo/Black</name>
            <uri>file://media/materials/scripts/gazebo.material</uri>
          </script>
	</material>
      </visual>
    </link>

    <!-- Ball -->
    <joint name="attach-ball" type="fixed">
      <parent>rod</parent>
      <child>ball</child>
      <pose relative_to="hinge">0 0 -1.0 0 0 0</pose>
    </joint>
    <link name="ball">
      <pose relative_to="attach-ball">0 0 0 0 0 0</pose>
      <inertial>
        <mass>0.200</mass>
        <inertia>
          <ixx>0.0008</ixx>
          <iyy>0.0008</iyy>
          <izz>0.0008</izz>
          <ixy>0</ixy>
          <ixz>0</ixz>
          <iyz>0</iyz>
        </inertia>
      </inertial>
      <collision name="collision">
        <geometry>
          <sphere>
            <radius>0.1</radius>
          </sphere>
        </geometry>
      </collision>
      <visual name="visual">
        <geometry>
          <sphere>
            <radius>0.1</radius>
          </sphere>
        </geometry>
	<material>
          <script>
            <name>Gazebo/Green</name>
            <uri>file://media/materials/scripts/gazebo.material</uri>
          </script>
	</material>
      </visual>
    </link>
  </model>
</sdf>
